Workbook

Sheet STOK
A1: Ürün ID | B1: SAP | C1: Güncel miktar | D1: Sipariş noktası
A2: 605002 | B2: 5398795 | C2: 5 | D2: 5
A3: 605003 | B3: 7243868 | C3: 8 | D3: 7
A4: 605004 | B4: 5290055 | C4: 5 | D4: 5
A5: 605005 | B5: 6680174 | C5: 0 | D5: 7
A6: 605006 | B6: 7243904 | C6: 7 | D6: 5
A7: 605007 | B7: 5652820 | C7: 20 | D7: 10
A8: 605008 | B8: 5652820 | C8: 12 | D8: 5
A9: 605009 | B9: 7269368 | C9: 2 | D9: 15
A10: 605010 | B10: 8016825 | C10: 0 | D10: 15
A11: 605012 | B11: 8026019 | C11: 6 | D11: 10
A12: 605013 | B12: 7425489 | C12: 0 | D12: 10
A13: 605015 | B13: 6907637 | C13: 8 | D13: 5
... A329: 8325036 | B329: 8325013 | C329: 0 | D329: 10
A330: R605002 | B330: 5398795 | C330: 6 | D330: 0
A331: R605010605713 | B331: 8016825 | C331: 56 | D331: 0
A332: R605016 | B332: 6961081 | C332: 22 | D332: 0
A333: R605021605095605267605391 | B333: 7105384 | C333: 25 | D333: 0
A334: R605022 | B334: 6682298 | C334: 11 | D334: 0
A335: R605024605066605167 | B335: 7105386 | C335: 2 | D335: 0
A336: R605025605694 | B336: 5398702 | C336: 9 | D336: 0
A337: R605026 | B337: 5834790 | C337: 64 | D337: 0
A338: R605027605112 | B338: 8012950 | C338: 9 | D338: 0
A339: R605029605707 | B339: 5691048 | C339: 13 | D339: 0
A340: R605030 | B340: 7244726 | C340: 86 | D340: 0
A341: R605032605309 | C341: 1 | D341: 0
A342: R605036605093605249 | B342: 6902777 | C342: 13 | D342: 0
A343: R605037605070605274 | B343: 6685094 | C343: 4 | D343: 0
A344: R605043605206 | B344: 6683830 | C344: 4 | D344: 0
A345: R605045 | B345: 7246592 | C345: 51 | D345: 0
A346: R605049605272605402 | B346: 6901527 | C346: 4 | D346: 0
A347: R605050605128 | B347: 8016824 | C347: 66 | D347: 0
A348: R605051 | B348: 5834802 | C348: 32 | D348: 0
A349: R605054 | B349: 5398789 | C349: 34 | D349: 0
A350: R605055605335 | B350: 7041014 | C350: 13 | D350: 0
A351: R605067 | B351: 7144515 | C351: 20 | D351: 0
A352: R605068 | B352: 7372454 | C352: 9 | D352: 0
A353: R605079 | B353: 7374102 | C353: 24 | D353: 0
... A397: R605009 | B397: 7269368 | C397: 2 | D397: 0
A398: R605616 | C398: 1 | D398: 0
...

Sheet DB
A1: TOOL | B1: SAP | C1: ALTERNATIVE
A2: 605002 | B2: 5398795
A3: 605003 | B3: 7243868 | C3: 605256
A4: 605004 | B4: 5290055
A5: 605005 | B5: 6680174 | C5: 605282 605505
A6: 605006 | B6: 7243904 | C6: 605317 605506
A7: 605007 | B7: 5652820 | C7: 605008 605122 605357 605358 605385
A8: 605008 | B8: 5652820 | C8: 605007 605122 605357 605358 605385
A9: 605009 | B9: 7269368
A10: 605010 | B10: 8016825 | C10: 605713
A11: 605012 | B11: 8026019
A12: 605013 | B12: 7425489 | C12: 605338 605667
A13: 605015 | B13: 6907637 | C13: 605251
A14: 605016 | B14: 6961081
A15: 605017 | B15: 7269365
A16: 605018 | B16: 6634856
A17: 605021 | B17: 7105384 | C17: 605095 605267
A18: 605022 | B18: 6682298
A19: 605023 | B19: 7366785
A20: 605024 | B20: 7105386 | C20: 605066 605167
A21: 605025 | B21: 5398702 | C21: 605694
A22: 605026 | B22: 5834790
A23: 605027 | B23: 8012950 | C23: 605112
A24: 605028 | B24: 7901960
A25: 605029 | B25: 5691048 | C25: 605707
A26: 605030 | B26: 7244726
A27: 605032 | B27: 6686663 | C27: 605309
A28: 605033 | B28: 5856728
A29: 605035 | B29: 7316495 | C29: 605283 605535
A30: 605036 | B30: 6902777 | C30: 605093 605249
A31: 605037 | B31: 6685094 | C31: 605070 605274
A32: 605038 | B32: 7275278
A33: 605039 | B33: 5073591 | C33: 605225
A34: 605040 | B34: 7269390
A35: 605041 | B35: 6015377
A36: 605042 | B36: 8214258
A37: 605043 | B37: 6683830 | C37: 605206
A38: 605044 | B38: 5834800
A39: 605045 | B39: 7246592
A40: 605048 | B40: 7242705 | C40: 605106 605257 605548
...

Sheet M5004.059-B19-04-03
A1: TAKIM | B1: STOK | C1: ALTERNATİF
A2: 605010 | B2: =_xlfn.XLOOKUP(A2,STOK!A:A,STOK!C:C, "***") -> 0 | C2: =IF(B2=0, IF(IFERROR(VLOOKUP(A2, DB!A:C, 3, FALSE), "")="", "Alternatif Yok", VLOOKUP(A2, DB!A:C, 3, FALSE)), "") -> 605713
A3: 605022 | B3: =_xlfn.XLOOKUP(A3,STOK!A:A,STOK!C:C, "***") -> 4 | C3: =IF(B3=0, IF(IFERROR(VLOOKUP(A3, DB!A:C, 3, FALSE), "")="", "Alternatif Yok", VLOOKUP(A3, DB!A:C, 3, FALSE)), "")
A4: 605029 | B4: =_xlfn.XLOOKUP(A4,STOK!A:A,STOK!C:C, "***") -> 0 | C4: =IF(B4=0, IF(IFERROR(VLOOKUP(A4, DB!A:C, 3, FALSE), "")="", "Alternatif Yok", VLOOKUP(A4, DB!A:C, 3, FALSE)), "") -> 605707
A5: 605079 | B5: =_xlfn.XLOOKUP(A5,STOK!A:A,STOK!C:C, "***") -> 11 | C5: =IF(B5=0, IF(IFERROR(VLOOKUP(A5, DB!A:C, 3, FALSE), "")="", "Alternatif Yok", VLOOKUP(A5, DB!A:C, 3, FALSE)), "")
A6: 605081 | B6: =_xlfn.XLOOKUP(A6,STOK!A:A,STOK!C:C, "***") -> 16 | C6: =IF(B6=0, IF(IFERROR(VLOOKUP(A6, DB!A:C, 3, FALSE), "")="", "Alternatif Yok", VLOOKUP(A6, DB!A:C, 3, FALSE)), "")
A7: 605239 | B7: =_xlfn.XLOOKUP(A7,STOK!A:A,STOK!C:C, "***") -> 0 | C7: =IF(B7=0, IF(IFERROR(VLOOKUP(A7, DB!A:C, 3, FALSE), "")="", "Alternatif Yok", VLOOKUP(A7, DB!A:C, 3, FALSE)), "") -> 605390
A8: 605255 | B8: =_xlfn.XLOOKUP(A8,STOK!A:A,STOK!C:C, "***") -> 1 | C8: =IF(B8=0, IF(IFERROR(VLOOKUP(A8, DB!A:C, 3, FALSE), "")="", "Alternatif Yok", VLOOKUP(A8, DB!A:C, 3, FALSE)), "")
A9: 605272 | B9: =_xlfn.XLOOKUP(A9,STOK!A:A,STOK!C:C, "***") -> 0 | C9: =IF(B9=0, IF(IFERROR(VLOOKUP(A9, DB!A:C, 3, FALSE), "")="", "Alternatif Yok", VLOOKUP(A9, DB!A:C, 3, FALSE)), "") -> 605049 605402
A10: 605278 | B10: =_xlfn.XLOOKUP(A10,STOK!A:A,STOK!C:C, "***") -> 0 | C10: =IF(B10=0, IF(IFERROR(VLOOKUP(A10, DB!A:C, 3, FALSE), "")="", "Alternatif Yok", VLOOKUP(A10, DB!A:C, 3, FALSE)), "") -> 605553
A11: 605286 | B11: =_xlfn.XLOOKUP(A11,STOK!A:A,STOK!C:C, "***") -> 0 | C11: =IF(B11=0, IF(IFERROR(VLOOKUP(A11, DB!A:C, 3, FALSE), "")="", "Alternatif Yok", VLOOKUP(A11, DB!A:C, 3, FALSE)), "") -> 605311
A12: 605320 | B12: =_xlfn.XLOOKUP(A12,STOK!A:A,STOK!C:C, "***") -> 7 | C12: =IF(B12=0, IF(IFERROR(VLOOKUP(A12, DB!A:C, 3, FALSE), "")="", "Alternatif Yok", VLOOKUP(A12, DB!A:C, 3, FALSE)), "")
A13: 605360 | B13: =_xlfn.XLOOKUP(A13,STOK!A:A,STOK!C:C, "***") -> 0 | C13: =IF(B13=0, IF(IFERROR(VLOOKUP(A13, DB!A:C, 3, FALSE), "")="", "Alternatif Yok", VLOOKUP(A13, DB!A:C, 3, FALSE)), "") -> Alternatif Yok
... A20: 605999 | B20: =_xlfn.XLOOKUP(A20,STOK!A:A,STOK!C:C, "***") -> *** | C20: =IF(B20=0, IF(IFERROR(VLOOKUP(A20, DB!A:C, 3, FALSE), "")="", "Alternatif Yok", VLOOKUP(A20, DB!A:C, 3, FALSE)), "")
